Workbook

Sheet README
A1: Health IBNR model: 2026-09 valuation (live formulas)
A3: How to use
A4: 1. Each category has Triangle (data), Ratios, Factors and Reserve sheets.
A5: 2. Type a link ratio into a yellow Override cell on a Factors sheet. Completion factors, ultimates, IBNR and the Summary recalculate.
A6: 3. Margin, CAE, the PMPM/B-F cut-off and backlog gross-up ratios are yellow cells on the Assumptions sheet.
A7: 4. Grey ratios on the Ratios sheets are excluded from the averages (see the Selections log in the exhibits workbook).
A8: 5. Expected PMPM (blue) comes from the Python trend fit: log-linear trend with calendar-month seasonality.
A10: Colour key: blue font = data input; yellow fill = judgment input; black = formula; grey fill = excluded ratio.
A11: Summary column 'Python engine' shows the model of record. 'Difference' should be zero until you change an input.

Sheet Summary
A1: Category | B1: Paid to date | C1: IBNR | D1: Margin | E1: CAE | F1: Total liability | G1: Python engine IBNR | H1: Difference
A2: Inpatient (ex. large) | B2: ='IP Reserve'!D47 | C2: ='IP Reserve'!L47 | D2: =C2*Assumptions!$B$4 | E2: =(C2+D2)*Assumptions!$B$5 | F2: =C2+D2+E2 | G2: 65138744 | H2: =C2-G2
A3: Outpatient | B3: ='OP Reserve'!D47 | C3: ='OP Reserve'!L47 | D3: =C3*Assumptions!$B$4 | E3: =(C3+D3)*Assumptions!$B$5 | F3: =C3+D3+E3 | G3: 71888260 | H3: =C3-G3
A4: Professional | B4: ='Prof Reserve'!D47 | C4: ='Prof Reserve'!L47 | D4: =C4*Assumptions!$B$4 | E4: =(C4+D4)*Assumptions!$B$5 | F4: =C4+D4+E4 | G4: 45653039 | H4: =C4-G4
A5: Large claims (>$250k) | B5: ='LC Reserve'!D47 | C5: ='LC Reserve'!L47 | D5: =C5*Assumptions!$B$4 | E5: =(C5+D5)*Assumptions!$B$5 | F5: =C5+D5+E5 | G5: 43566758 | H5: =C5-G5
A6: Total | B6: =SUM(B2:B5) | C6: =SUM(C2:C5) | D6: =SUM(D2:D5) | E6: =SUM(E2:E5) | F6: =SUM(F2:F5) | G6: =SUM(G2:G5) | H6: =SUM(H2:H5)

Sheet Assumptions
A1: Assumption | B1: Value | C1: Note
A2: Valuation month | B2: 2026-09 | C2: Paid-through month
A3: PMPM / B-F months | B3: 3 | C3: Incurred months younger than this lag use B-F on the PMPM expected
A4: Margin % | B4: 0.075 | C4: Provision for adverse deviation on IBNR
A5: CAE % | B5: 0.025 | C5: Claim adjustment expense on IBNR + margin
A6: Backlog gross-up ratio: IP | B6: 1 | C6: Paid in valuation month / (paid + excess pended). 1.0 = no backlog
A7: Backlog gross-up ratio: OP | B7: 1 | C7: Paid in valuation month / (paid + excess pended). 1.0 = no backlog
A8: Backlog gross-up ratio: Prof | B8: 1 | C8: Paid in valuation month / (paid + excess pended). 1.0 = no backlog
A9: Backlog gross-up ratio: LC | B9: 1 | C9: Paid in valuation month / (paid + excess pended). 1.0 = no backlog

Sheet IP Triangle
A1: Incurred | B1: Lag 0 | C1: Lag 1 | D1: Lag 2 | E1: Lag 3 | F1: Lag 4 | G1: Lag 5 | H1: Lag 6 | I1: Lag 7 | J1: Lag 8 | K1: Lag 9 | L1: Lag 10 | M1: Lag 11 | N1: Lag 12 | O1: Lag 13 | P1: Lag 14 | Q1: Lag 15 | R1: Lag 16 | S1: Lag 17 | T1: Lag 18 | U1: Lag 19 | V1: Lag 20 | W1: Lag 21 | X1: Lag 22 | Y1: Lag 23 | Z1: Lag 24 | AA1: Lag 25 | AB1: Lag 26 | AC1: Lag 27 | AD1: Lag 28 | AE1: Lag 29 | AF1: Lag 30 | AG1: Lag 31 | AH1: Lag 32 | AI1: Lag 33 | AJ1: Lag 34 | AK1: Lag 35 | AL1: Lag 36 | AM1: Lag 37 | AN1: Lag 38 | AO1: Lag 39 | AP1: Lag 40 | AQ1: Lag 41 | AR1: Lag 42 | AS1: Lag 43 | AT1: Lag 44
A2: 2023-01 | B2: 2223686.8 | C2: 5991719.2 | D2: 9146020.4 | E2: 11433879 | F2: 13078776 | G2: 14116374 | H2: 14882654 | I2: 15365672 | J2: 15680081 | K2: 15909958 | L2: 16066729 | M2: 16163140 | N2: 16225892 | O2: 16265585 | P2: 16293209 | Q2: 16311612 | R2: 16322833 | S2: 16330220 | T2: 16335166 | U2: 16338309 | V2: 16340339 | W2: 16341645 | X2: 16342513 | Y2: 16343082 | Z2: 16343450 | AA2: 16343677 | AB2: 16343837 | AC2: 16343938 | AD2: 16344001 | AE2: 16344041 | AF2: 16344069 | AG2: 16344086 | AH2: 16344098 | AI2: 16344105 | AJ2: 16344110 | AK2: 16344113 | AL2: 16344115 | AM2: 16344115 | AN2: 16344115 | AO2: 16344115 | AP2: 16344115 | AQ2: 16344115 | AR2: 16344115 | AS2: 16344115 | AT2: 16344115
A3: 2023-02 | B3: 2294770.3 | C3: 6313241.1 | D3: 9617771.7 | E3: 11964281 | F3: 13599746 | G3: 14666615 | H3: 15428321 | I3: 15941453 | J3: 16277440 | K3: 16485326 | L3: 16623272 | M3: 16724738 | N3: 16789299 | O3: 16829593 | P3: 16854904 | Q3: 16872264 | R3: 16884021 | S3: 16891619 | T3: 16896559 | U3: 16899797 | V3: 16901892 | W3: 16903236 | X3: 16904144 | Y3: 16904695 | Z3: 16905043 | AA3: 16905267 | AB3: 16905419 | AC3: 16905515 | AD3: 16905580 | AE3: 16905621 | AF3: 16905646 | AG3: 16905662 | AH3: 16905674 | AI3: 16905681 | AJ3: 16905685 | AK3: 16905688 | AL3: 16905690 | AM3: 16905690 | AN3: 16905690 | AO3: 16905690 | AP3: 16905690 | AQ3: 16905690 | AR3: 16905690 | AS3: 16905690
A4: 2023-03 | B4: 2368953.5 | C4: 6658129.5 | D4: 9946001.7 | E4: 12324762 | F4: 14083626 | G4: 15138009 | H4: 15908506 | I4: 16432138 | J4: 16782346 | K4: 17015599 | L4: 17169823 | M4: 17269910 | N4: 17334685 | O4: 17377833 | P4: 17407385 | Q4: 17426039 | R4: 17438342 | S4: 17445760 | T4: 17450587 | U4: 17453859 | V4: 17456012 | W4: 17457429 | X4: 17458358 | Y4: 17458913 | Z4: 17459277 | AA4: 17459514 | AB4: 17459665 | AC4: 17459764 | AD4: 17459828 | AE4: 17459871 | AF4: 17459899 | AG4: 17459916 | AH4: 17459927 | AI4: 17459935 | AJ4: 17459939 | AK4: 17459942 | AL4: 17459944 | AM4: 17459944 | AN4: 17459944 | AO4: 17459944 | AP4: 17459944 | AQ4: 17459944 | AR4: 17459944
A5: 2023-04 | B5: 2643028.1 | C5: 7482429.9 | D5: 11171610 | E5: 13870489 | F5: 15789694 | G5: 17103903 | H5: 17929679 | I5: 18561550 | J5: 18959715 | K5: 19209218 | L5: 19381907 | M5: 19493398 | N5: 19563454 | O5: 19611364 | P5: 19641902 | Q5: 19661937 | R5: 19674532 | S5: 19683092 | T5: 19688657 | U5: 19692185 | V5: 19694612 | W5: 19696090 | X5: 19697065 | Y5: 19697691 | Z5: 19698105 | AA5: 19698363 | AB5: 19698532 | AC5: 19698641 | AD5: 19698713 | AE5: 19698756 | AF5: 19698786 | AG5: 19698807 | AH5: 19698819 | AI5: 19698827 | AJ5: 19698831 | AK5: 19698835 | AL5: 19698837 | AM5: 19698837 | AN5: 19698837 | AO5: 19698837 | AP5: 19698837 | AQ5: 19698837
A6: 2023-05 | B6: 2424616 | C6: 7317241.1 | D6: 10733832 | E6: 13169383 | F6: 14867488 | G6: 16038729 | H6: 16849514 | I6: 17362566 | J6: 17695552 | K6: 17928174 | L6: 18077216 | M6: 18178841 | N6: 18251113 | O6: 18295009 | P6: 18322227 | Q6: 18340430 | R6: 18352384 | S6: 18359838 | T6: 18364937 | U6: 18368146 | V6: 18370294 | W6: 18371666 | X6: 18372471 | Y6: 18373035 | Z6: 18373385 | AA6: 18373613 | AB6: 18373759 | AC6: 18373856 | AD6: 18373916 | AE6: 18373956 | AF6: 18373981 | AG6: 18373997 | AH6: 18374007 | AI6: 18374014 | AJ6: 18374018 | AK6: 18374021 | AL6: 18374023 | AM6: 18374023 | AN6: 18374023 | AO6: 18374023 | AP6: 18374023
A7: 2023-06 | B7: 2342849.5 | C7: 6620503.3 | D7: 10120072 | E7: 12563985 | F7: 14219875 | G7: 15401418 | H7: 16167807 | I7: 16679337 | J7: 17002780 | K7: 17226281 | L7: 17379300 | M7: 17476356 | N7: 17539938 | O7: 17579934 | P7: 17606580 | Q7: 17623068 | R7: 17634419 | S7: 17641607 | T7: 17646383 | U7: 17649278 | V7: 17651360 | W7: 17652672 | X7: 17653532 | Y7: 17654077 | Z7: 17654428 | AA7: 17654662 | AB7: 17654805 | AC7: 17654900 | AD7: 17654957 | AE7: 17654995 | AF7: 17655018 | AG7: 17655034 | AH7: 17655044 | AI7: 17655051 | AJ7: 17655055 | AK7: 17655058 | AL7: 17655059 | AM7: 17655059 | AN7: 17655059 | AO7: 17655059
A8: 2023-07 | B8: 2455059.7 | C8: 7031679.7 | D8: 10375866 | E8: 12804400 | F8: 14473942 | G8: 15683641 | H8: 16493146 | I8: 17054698 | J8: 17401961 | K8: 17629648 | L8: 17773857 | M8: 17871292 | N8: 17937391 | O8: 17979599 | P8: 18007120 | Q8: 18025150 | R8: 18036454 | S8: 18043731 | T8: 18048604 | U8: 18051675 | V8: 18053634 | W8: 18054985 | X8: 18055832 | Y8: 18056361 | Z8: 18056698 | AA8: 18056906 | AB8: 18057051 | AC8: 18057141 | AD8: 18057201 | AE8: 18057238 | AF8: 18057262 | AG8: 18057278 | AH8: 18057288 | AI8: 18057294 | AJ8: 18057298 | AK8: 18057301 | AL8: 18057303 | AM8: 18057303 | AN8: 18057303
A9: 2023-08 | B9: 2486264.4 | C9: 7358804.5 | D9: 10960525 | E9: 13491504 | F9: 15278002 | G9: 16534196 | H9: 17338812 | I9: 17869202 | J9: 18229554 | K9: 18465629 | L9: 18613564 | M9: 18710873 | N9: 18776648 | O9: 18819936 | P9: 18848639 | Q9: 18866692 | R9: 18878251 | S9: 18885430 | T9: 18890393 | U9: 18893623 | V9: 18895616 | W9: 18896910 | X9: 18897715 | Y9: 18898251 | Z9: 18898602 | AA9: 18898830 | AB9: 18898964 | AC9: 18899053 | AD9: 18899109 | AE9: 18899147 | AF9: 18899171 | AG9: 18899186 | AH9: 18899195 | AI9: 18899201 | AJ9: 18899205 | AK9: 18899208 | AL9: 18899210 | AM9: 18899210
A10: 2023-09 | B10: 2434282.7 | C10: 6939321.2 | D10: 10441862 | E10: 12854952 | F10: 14570694 | G10: 15715482 | H10: 16474994 | I10: 16968907 | J10: 17304059 | K10: 17517592 | L10: 17659742 | M10: 17755057 | N10: 17817610 | O10: 17856852 | P10: 17882032 | Q10: 17898196 | R10: 17909142 | S10: 17916191 | T10: 17920774 | U10: 17923553 | V10: 17925440 | W10: 17926612 | X10: 17927410 | Y10: 17927926 | Z10: 17928245 | AA10: 17928441 | AB10: 17928569 | AC10: 17928652 | AD10: 17928707 | AE10: 17928740 | AF10: 17928763 | AG10: 17928778 | AH10: 17928787 | AI10: 17928793 | AJ10: 17928797 | AK10: 17928799 | AL10: 17928801
A11: 2023-10 | B11: 2612330.9 | C11: 7331311.5 | D11: 10995055 | E11: 13705527 | F11: 15467140 | G11: 16707348 | H11: 17556030 | I11: 18095482 | J11: 18452606 | K11: 18688516 | L11: 18842168 | M11: 18942327 | N11: 19004480 | O11: 19045813 | P11: 19072885 | Q11: 19090481 | R11: 19101410 | S11: 19108690 | T11: 19113652 | U11: 19116735 | V11: 19118654 | W11: 19119901 | X11: 19120721 | Y11: 19121242 | Z11: 19121578 | AA11: 19121808 | AB11: 19121946 | AC11: 19122033 | AD11: 19122089 | AE11: 19122124 | AF11: 19122148 | AG11: 19122163 | AH11: 19122170 | AI11: 19122177 | AJ11: 19122181 | AK11: 19122184
A12: 2023-11 | B12: 2476255.6 | C12: 7067072.7 | D12: 10778528 | E12: 13412667 | F12: 15232059 | G12: 16451105 | H12: 17292566 | I12: 17822223 | J12: 18168628 | K12: 18395348 | L12: 18543373 | M12: 18639623 | N12: 18704591 | O12: 18744374 | P12: 18769843 | Q12: 18787236 | R12: 18797706 | S12: 18804712 | T12: 18809216 | U12: 18812116 | V12: 18814028 | W12: 18815215 | X12: 18815965 | Y12: 18816450 | Z12: 18816770 | AA12: 18816985 | AB12: 18817110 | AC12: 18817193 | AD12: 18817247 | AE12: 18817280 | AF12: 18817302 | AG12: 18817314 | AH12: 18817324 | AI12: 18817330 | AJ12: 18817333
A13: 2023-12 | B13: 3016686.1 | C13: 8502841.5 | D13: 12752657 | E13: 15841933 | F13: 17985060 | G13: 19366547 | H13: 20299795 | I13: 20921321 | J13: 21302646 | K13: 21567625 | L13: 21739366 | M13: 21854954 | N13: 21927195 | O13: 21975957 | P13: 22006759 | Q13: 22027084 | R13: 22040276 | S13: 22048028 | T13: 22053107 | U13: 22056366 | V13: 22058564 | W13: 22059934 | X13: 22060797 | Y13: 22061364 | Z13: 22061726 | AA13: 22061970 | AB13: 22062116 | AC13: 22062215 | AD13: 22062274 | AE13: 22062316 | AF13: 22062338 | AG13: 22062356 | AH13: 22062366 | AI13: 22062372
A14: 2024-01 | B14: 2918876.3 | C14: 8030524.1 | D14: 11818589 | E14: 14629218 | F14: 16613604 | G14: 17911515 | H14: 18760078 | I14: 19313479 | J14: 19683619 | K14: 19938132 | L14: 20088484 | M14: 20195357 | N14: 20262998 | O14: 20306140 | P14: 20333113 | Q14: 20351035 | R14: 20362797 | S14: 20370166 | T14: 20374804 | U14: 20377769 | V14: 20379694 | W14: 20380951 | X14: 20381777 | Y14: 20382287 | Z14: 20382611 | AA14: 20382823 | AB14: 20382952 | AC14: 20383038 | AD14: 20383091 | AE14: 20383120 | AF14: 20383147 | AG14: 20383161 | AH14: 20383169
A15: 2024-02 | B15: 2708480.4 | C15: 7914023.9 | D15: 11613089 | E15: 14207421 | F15: 15897064 | G15: 17107858 | H15: 17895099 | I15: 18419271 | J15: 18754605 | K15: 18982874 | L15: 19133729 | M15: 19232004 | N15: 19294029 | O15: 19331936 | P15: 19357926 | Q15: 19374760 | R15: 19385286 | S15: 19391576 | T15: 19395703 | U15: 19398489 | V15: 19400235 | W15: 19401463 | X15: 19402160 | Y15: 19402622 | Z15: 19402932 | AA15: 19403118 | AB15: 19403242 | AC15: 19403315 | AD15: 19403359 | AE15: 19403395 | AF15: 19403415 | AG15: 19403427
A16: 2024-03 | B16: 2642112.8 | C16: 7532822.5 | D16: 11554169 | E16: 14212668 | F16: 16192306 | G16: 17516320 | H16: 18324778 | I16: 18895029 | J16: 19242518 | K16: 19485679 | L16: 19635856 | M16: 19736392 | N16: 19798307 | O16: 19841068 | P16: 19868222 | Q16: 19885515 | R16: 19896805 | S16: 19903623 | T16: 19908004 | U16: 19910950 | V16: 19912744 | W16: 19913904 | X16: 19914675 | Y16: 19915138 | Z16: 19915438 | AA16: 19915622 | AB16: 19915741 | AC16: 19915809 | AD16: 19915867 | AE16: 19915899 | AF16: 19915920
A17: 2024-04 | B17: 2864228.9 | C17: 8200510.1 | D17: 12390556 | E17: 15436815 | F17: 17393873 | G17: 18798316 | H17: 19718729 | I17: 20301645 | J17: 20698993 | K17: 20958795 | L17: 21114444 | M17: 21220008 | N17: 21289621 | O17: 21334615 | P17: 21363198 | Q17: 21380764 | R17: 21392169 | S17: 21399568 | T17: 21404167 | U17: 21407327 | V17: 21409294 | W17: 21410497 | X17: 21411280 | Y17: 21411781 | Z17: 21412104 | AA17: 21412301 | AB17: 21412412 | AC17: 21412510 | AD17: 21412561 | AE17: 21412595
A18: 2024-05 | B18: 2878060.9 | C18: 8291529.6 | D18: 12645848 | E18: 15729412 | F18: 17796838 | G18: 19194100 | H18: 20102427 | I18: 20731641 | J18: 21129840 | K18: 21384385 | L18: 21556446 | M18: 21666511 | N18: 21735871 | O18: 21780503 | P18: 21808956 | Q18: 21827610 | R18: 21839567 | S18: 21847178 | T18: 21851900 | U18: 21854837 | V18: 21856803 | W18: 21858054 | X18: 21858840 | Y18: 21859333 | Z18: 21859652 | AA18: 21859841 | AB18: 21859993 | AC18: 21860077 | AD18: 21860130
A19: 2024-06 | B19: 2843018.6 | C19: 8208312.3 | D19: 12222789 | E19: 15056763 | F19: 17002160 | G19: 18283703 | H19: 19177112 | I19: 19739417 | J19: 20112970 | K19: 20344615 | L19: 20493280 | M19: 20595674 | N19: 20659553 | O19: 20698486 | P19: 20725479 | Q19: 20742048 | R19: 20753048 | S19: 20759784 | T19: 20763997 | U19: 20766670 | V19: 20768405 | W19: 20769581 | X19: 20770303 | Y19: 20770737 | Z19: 20770974 | AA19: 20771183 | AB19: 20771291 | AC19: 20771358
A20: 2024-07 | B20: 2705308.4 | C20: 7935499 | D20: 12013299 | E20: 14731646 | F20: 16571050 | G20: 17791115 | H20: 18648782 | I20: 19184111 | J20: 19564720 | K20: 19794947 | L20: 19952473 | M20: 20053224 | N20: 20113827 | O20: 20153306 | P20: 20178837 | Q20: 20194765 | R20: 20204913 | S20: 20211714 | T20: 20215979 | U20: 20218753 | V20: 20220481 | W20: 20221593 | X20: 20222274 | Y20: 20222667 | Z20: 20222990 | AA20: 20223165 | AB20: 20223278
A21: 2024-08 | B21: 3151649.3 | C21: 8248249 | D21: 12281399 | E21: 15261588 | F21: 17282585 | G21: 18695152 | H21: 19594409 | I21: 20194232 | J21: 20572661 | K21: 20808033 | L21: 20962469 | M21: 21070088 | N21: 21135512 | O21: 21177349 | P21: 21204211 | Q21: 21221079 | R21: 21232021 | S21: 21238628 | T21: 21243036 | U21: 21245765 | V21: 21247531 | W21: 21248638 | X21: 21249264 | Y21: 21249796 | Z21: 21250087 | AA21: 21250258
A22: 2024-09 | B22: 2921301.6 | C22: 8284699.8 | D22: 12421179 | E22: 15221395 | F22: 17118539 | G22: 18429811 | H22: 19264388 | I22: 19838820 | J22: 20191635 | K22: 20427470 | L22: 20574078 | M22: 20668628 | N22: 20729941 | O22: 20769621 | P22: 20793330 | Q22: 20809398 | R22: 20819367 | S22: 20825715 | T22: 20829853 | U22: 20832442 | V22: 20834049 | W22: 20834962 | X22: 20835736 | Y22: 20836147 | Z22: 20836402
A23: 2024-10 | B23: 3291786.1 | C23: 9208576.7 | D23: 13706672 | E23: 16875447 | F23: 18979375 | G23: 20385471 | H23: 21276019 | I23: 21879977 | J23: 22289863 | K23: 22542519 | L23: 22710128 | M23: 22817528 | N23: 22885694 | O23: 22928270 | P23: 22956287 | Q23: 22972799 | R23: 22983833 | S23: 22990538 | T23: 22994862 | U23: 22997569 | V23: 22999135 | W23: 23000436 | X23: 23001195 | Y23: 23001650
A24: 2024-11 | B24: 3237868.6 | C24: 8900497.7 | D24: 13321459 | E24: 16496883 | F24: 18574340 | G24: 19959925 | H24: 20863975 | I24: 21453420 | J24: 21838020 | K24: 22089920 | L24: 22245356 | M24: 22346962 | N24: 22415921 | O24: 22455644 | P24: 22482804 | Q24: 22499286 | R24: 22509905 | S24: 22516604 | T24: 22520810 | U24: 22523262 | V24: 22525341 | W24: 22526431 | X24: 22527149
A25: 2024-12 | B25: 3473698 | C25: 9626924.6 | D25: 14185378 | E25: 17440838 | F25: 19779385 | G25: 21278426 | H25: 22251458 | I25: 22884693 | J25: 23284994 | K25: 23545909 | L25: 23708147 | M25: 23816917 | N25: 23884317 | O25: 23929991 | P25: 23956561 | Q25: 23974153 | R25: 23984847 | S25: 23992078 | T25: 23995980 | U25: 23999320 | V25: 24001056 | W25: 24002178
A26: 2025-01 | B26: 3227119.6 | C26: 9079173.6 | D26: 13335349 | E26: 16449771 | F26: 18692097 | G26: 20048582 | H26: 21006752 | I26: 21587602 | J26: 21957498 | K26: 22192544 | L26: 22346362 | M26: 22442380 | N26: 22506753 | O26: 22547045 | P26: 22572698 | Q26: 22589575 | R26: 22600074 | S26: 22605784 | T26: 22610646 | U26: 22613196 | V26: 22614794
A27: 2025-02 | B27: 2969490.7 | C27: 8688017.8 | D27: 12674290 | E27: 15636116 | F27: 17515323 | G27: 18824044 | H27: 19714970 | I27: 20281723 | J27: 20648523 | K27: 20874874 | L27: 21018149 | M27: 21110924 | N27: 21170040 | O27: 21207328 | P27: 21231282 | Q27: 21245806 | R27: 21254121 | S27: 21261223 | T27: 21264994 | U27: 21267310
A28: 2025-03 | B28: 3019875.6 | C28: 8344612.5 | D28: 12575652 | E28: 15634406 | F28: 17594444 | G28: 18953808 | H28: 19844793 | I28: 20374177 | J28: 20732292 | K28: 20977759 | L28: 21119114 | M28: 21211247 | N28: 21270776 | O28: 21309669 | P28: 21333405 | Q28: 21346723 | R28: 21358227 | S28: 21364276 | T28: 21368088
A29: 2025-04 | B29: 3528729.5 | C29: 9328168.5 | D29: 13809156 | E29: 17066464 | F29: 19158586 | G29: 20535847 | H29: 21461068 | I29: 22022485 | J29: 22405804 | K29: 22657820 | L29: 22817064 | M29: 22910578 | N29: 22970975 | O29: 23011096 | P29: 23032838 | Q29: 23051867 | R29: 23062309 | S29: 23068652
A30: 2025-05 | B30: 3275776.9 | C30: 9253777.1 | D30: 13701090 | E30: 16941084 | F30: 19063974 | G30: 20470184 | H30: 21401098 | I30: 22002551 | J30: 22371444 | K30: 22623592 | L30: 22778324 | M30: 22876143 | N30: 22939205 | O30: 22973306 | P30: 23001214 | Q30: 23016030 | R30: 23026182
A31: 2025-06 | B31: 3517443.9 | C31: 9920730.4 | D31: 14314060 | E31: 17501467 | F31: 19549387 | G31: 21007382 | H31: 21946286 | I31: 22557094 | J31: 22965556 | K31: 23212981 | L31: 23363545 | M31: 23463727 | N31: 23519468 | O31: 23566596 | P31: 23590300 | Q31: 23605034
A32: 2025-07 | B32: 3356398.2 | C32: 9393397.3 | D32: 13786555 | E32: 16786351 | F32: 18847537 | G32: 20340118 | H32: 21214887 | I32: 21795223 | J32: 22192546 | K32: 22425910 | L32: 22578459 | M32: 22661568 | N32: 22735787 | O32: 22774371 | P32: 22797932
A33: 2025-08 | B33: 3141229.6 | C33: 8813975.1 | D33: 13205570 | E33: 16330444 | F33: 18287202 | G33: 19633209 | H33: 20502647 | I33: 21012780 | J33: 21360619 | K33: 21590674 | L33: 21716376 | M33: 21826043 | N33: 21882254 | O33: 21918180
A34: 2025-09 | B34: 3412715.4 | C34: 10059927 | D34: 14571999 | E34: 17791379 | F34: 19948525 | G34: 21372245 | H34: 22290308 | I34: 22881516 | J34: 23249983 | K34: 23452087 | L34: 23625427 | M34: 23717346 | N34: 23777837
A35: 2025-10 | B35: 3830933.8 | C35: 10614910 | D35: 15586167 | E35: 18972141 | F35: 21405304 | G35: 22894622 | H35: 23883568 | I35: 24521337 | J35: 24851096 | K35: 25143650 | L35: 25310532 | M35: 25410117
A36: 2025-11 | B36: 3868183.5 | C36: 10995690 | D36: 16000478 | E36: 19255825 | F36: 21529367 | G36: 23053046 | H36: 24035263 | I36: 24578330 | J36: 25042423 | K36: 25295194 | L36: 25449717
A37: 2025-12 | B37: 4082932.6 | C37: 11258057 | D37: 16391566 | E37: 20002411 | F37: 22579644 | G37: 24196386 | H37: 25106293 | I37: 25906603 | J37: 26331105 | K37: 26592485
A38: 2026-01 | B38: 3551488.8 | C38: 9742748.7 | D38: 14225638 | E38: 17333405 | F38: 19491103 | G38: 20639483 | H38: 21688923 | I38: 22242263 | J38: 22605863
A39: 2026-02 | B39: 3832070.7 | C39: 10502602 | D39: 15340847 | E39: 18769410 | F39: 20820174 | G39: 22515091 | H39: 23485931 | I39: 24061764
A40: 2026-03 | B40: 3702489.9 | C40: 10162880 | D40: 14908747 | E40: 17992734 | F40: 20598786 | G40: 22119629 | H40: 23041091
...

Sheet IP Ratios
A1: Incurred | B1: 0-1 | C1: 1-2 | D1: 2-3 | E1: 3-4 | F1: 4-5 | G1: 5-6 | H1: 6-7 | I1: 7-8 | J1: 8-9 | K1: 9-10 | L1: 10-11 | M1: 11-12 | N1: 12-13 | O1: 13-14 | P1: 14-15 | Q1: 15-16 | R1: 16-17 | S1: 17-18 | T1: 18-19 | U1: 19-20 | V1: 20-21 | W1: 21-22 | X1: 22-23 | Y1: 23-24 | Z1: 24-25 | AA1: 25-26 | AB1: 26-27 | AC1: 27-28 | AD1: 28-29 | AE1: 29-30 | AF1: 30-31 | AG1: 31-32 | AH1: 32-33 | AI1: 33-34 | AJ1: 34-35 | AK1: 35-36 | AL1: 36-37 | AM1: 37-38 | AN1: 38-39 | AO1: 39-40 | AP1: 40-41 | AQ1: 41-42 | AR1: 42-43 | AS1: 43-44
A2: 2023-01 | B2: =IF('IP Triangle'!B2>0,'IP Triangle'!C2/'IP Triangle'!B2,"") | C2: =IF('IP Triangle'!C2>0,'IP Triangle'!D2/'IP Triangle'!C2,"") | D2: =IF('IP Triangle'!D2>0,'IP Triangle'!E2/'IP Triangle'!D2,"") | E2: =IF('IP Triangle'!E2>0,'IP Triangle'!F2/'IP Triangle'!E2,"") | F2: =IF('IP Triangle'!F2>0,'IP Triangle'!G2/'IP Triangle'!F2,"") | G2: =IF('IP Triangle'!G2>0,'IP Triangle'!H2/'IP Triangle'!G2,"") | H2: =IF('IP Triangle'!H2>0,'IP Triangle'!I2/'IP Triangle'!H2,"") | I2: =IF('IP Triangle'!I2>0,'IP Triangle'!J2/'IP Triangle'!I2,"") | ... AS2: =IF('IP Triangle'!AS2>0,'IP Triangle'!AT2/'IP Triangle'!AS2,"")
A3: 2023-02 | B3: =IF('IP Triangle'!B3>0,'IP Triangle'!C3/'IP Triangle'!B3,"") | C3: =IF('IP Triangle'!C3>0,'IP Triangle'!D3/'IP Triangle'!C3,"") | D3: =IF('IP Triangle'!D3>0,'IP Triangle'!E3/'IP Triangle'!D3,"") | E3: =IF('IP Triangle'!E3>0,'IP Triangle'!F3/'IP Triangle'!E3,"") | F3: =IF('IP Triangle'!F3>0,'IP Triangle'!G3/'IP Triangle'!F3,"") | G3: =IF('IP Triangle'!G3>0,'IP Triangle'!H3/'IP Triangle'!G3,"") | H3: =IF('IP Triangle'!H3>0,'IP Triangle'!I3/'IP Triangle'!H3,"") | I3: =IF('IP Triangle'!I3>0,'IP Triangle'!J3/'IP Triangle'!I3,"") | ... AR3: =IF('IP Triangle'!AR3>0,'IP Triangle'!AS3/'IP Triangle'!AR3,"")
A4: 2023-03 | B4: =IF('IP Triangle'!B4>0,'IP Triangle'!C4/'IP Triangle'!B4,"") | C4: =IF('IP Triangle'!C4>0,'IP Triangle'!D4/'IP Triangle'!C4,"") | D4: =IF('IP Triangle'!D4>0,'IP Triangle'!E4/'IP Triangle'!D4,"") | E4: =IF('IP Triangle'!E4>0,'IP Triangle'!F4/'IP Triangle'!E4,"") | F4: =IF('IP Triangle'!F4>0,'IP Triangle'!G4/'IP Triangle'!F4,"") | G4: =IF('IP Triangle'!G4>0,'IP Triangle'!H4/'IP Triangle'!G4,"") | H4: =IF('IP Triangle'!H4>0,'IP Triangle'!I4/'IP Triangle'!H4,"") | I4: =IF('IP Triangle'!I4>0,'IP Triangle'!J4/'IP Triangle'!I4,"") | ... AQ4: =IF('IP Triangle'!AQ4>0,'IP Triangle'!AR4/'IP Triangle'!AQ4,"")
A5: 2023-04 | B5: =IF('IP Triangle'!B5>0,'IP Triangle'!C5/'IP Triangle'!B5,"") | C5: =IF('IP Triangle'!C5>0,'IP Triangle'!D5/'IP Triangle'!C5,"") | D5: =IF('IP Triangle'!D5>0,'IP Triangle'!E5/'IP Triangle'!D5,"") | E5: =IF('IP Triangle'!E5>0,'IP Triangle'!F5/'IP Triangle'!E5,"") | F5: =IF('IP Triangle'!F5>0,'IP Triangle'!G5/'IP Triangle'!F5,"") | G5: =IF('IP Triangle'!G5>0,'IP Triangle'!H5/'IP Triangle'!G5,"") | H5: =IF('IP Triangle'!H5>0,'IP Triangle'!I5/'IP Triangle'!H5,"") | I5: =IF('IP Triangle'!I5>0,'IP Triangle'!J5/'IP Triangle'!I5,"") | ... AP5: =IF('IP Triangle'!AP5>0,'IP Triangle'!AQ5/'IP Triangle'!AP5,"")
A6: 2023-05 | B6: =IF('IP Triangle'!B6>0,'IP Triangle'!C6/'IP Triangle'!B6,"") | C6: =IF('IP Triangle'!C6>0,'IP Triangle'!D6/'IP Triangle'!C6,"") | D6: =IF('IP Triangle'!D6>0,'IP Triangle'!E6/'IP Triangle'!D6,"") | E6: =IF('IP Triangle'!E6>0,'IP Triangle'!F6/'IP Triangle'!E6,"") | F6: =IF('IP Triangle'!F6>0,'IP Triangle'!G6/'IP Triangle'!F6,"") | G6: =IF('IP Triangle'!G6>0,'IP Triangle'!H6/'IP Triangle'!G6,"") | H6: =IF('IP Triangle'!H6>0,'IP Triangle'!I6/'IP Triangle'!H6,"") | I6: =IF('IP Triangle'!I6>0,'IP Triangle'!J6/'IP Triangle'!I6,"") | ... AO6: =IF('IP Triangle'!AO6>0,'IP Triangle'!AP6/'IP Triangle'!AO6,"")
A7: 2023-06 | B7: =IF('IP Triangle'!B7>0,'IP Triangle'!C7/'IP Triangle'!B7,"") | C7: =IF('IP Triangle'!C7>0,'IP Triangle'!D7/'IP Triangle'!C7,"") | D7: =IF('IP Triangle'!D7>0,'IP Triangle'!E7/'IP Triangle'!D7,"") | E7: =IF('IP Triangle'!E7>0,'IP Triangle'!F7/'IP Triangle'!E7,"") | F7: =IF('IP Triangle'!F7>0,'IP Triangle'!G7/'IP Triangle'!F7,"") | G7: =IF('IP Triangle'!G7>0,'IP Triangle'!H7/'IP Triangle'!G7,"") | H7: =IF('IP Triangle'!H7>0,'IP Triangle'!I7/'IP Triangle'!H7,"") | I7: =IF('IP Triangle'!I7>0,'IP Triangle'!J7/'IP Triangle'!I7,"") | ... AN7: =IF('IP Triangle'!AN7>0,'IP Triangle'!AO7/'IP Triangle'!AN7,"")
A8: 2023-07 | B8: =IF('IP Triangle'!B8>0,'IP Triangle'!C8/'IP Triangle'!B8,"") | C8: =IF('IP Triangle'!C8>0,'IP Triangle'!D8/'IP Triangle'!C8,"") | D8: =IF('IP Triangle'!D8>0,'IP Triangle'!E8/'IP Triangle'!D8,"") | E8: =IF('IP Triangle'!E8>0,'IP Triangle'!F8/'IP Triangle'!E8,"") | F8: =IF('IP Triangle'!F8>0,'IP Triangle'!G8/'IP Triangle'!F8,"") | G8: =IF('IP Triangle'!G8>0,'IP Triangle'!H8/'IP Triangle'!G8,"") | H8: =IF('IP Triangle'!H8>0,'IP Triangle'!I8/'IP Triangle'!H8,"") | I8: =IF('IP Triangle'!I8>0,'IP Triangle'!J8/'IP Triangle'!I8,"") | ... AM8: =IF('IP Triangle'!AM8>0,'IP Triangle'!AN8/'IP Triangle'!AM8,"")
A9: 2023-08 | B9: =IF('IP Triangle'!B9>0,'IP Triangle'!C9/'IP Triangle'!B9,"") | C9: =IF('IP Triangle'!C9>0,'IP Triangle'!D9/'IP Triangle'!C9,"") | D9: =IF('IP Triangle'!D9>0,'IP Triangle'!E9/'IP Triangle'!D9,"") | E9: =IF('IP Triangle'!E9>0,'IP Triangle'!F9/'IP Triangle'!E9,"") | F9: =IF('IP Triangle'!F9>0,'IP Triangle'!G9/'IP Triangle'!F9,"") | G9: =IF('IP Triangle'!G9>0,'IP Triangle'!H9/'IP Triangle'!G9,"") | H9: =IF('IP Triangle'!H9>0,'IP Triangle'!I9/'IP Triangle'!H9,"") | I9: =IF('IP Triangle'!I9>0,'IP Triangle'!J9/'IP Triangle'!I9,"") | ... AL9: =IF('IP Triangle'!AL9>0,'IP Triangle'!AM9/'IP Triangle'!AL9,"")
A10: 2023-09 | B10: =IF('IP Triangle'!B10>0,'IP Triangle'!C10/'IP Triangle'!B10,"") | C10: =IF('IP Triangle'!C10>0,'IP Triangle'!D10/'IP Triangle'!C10,"") | D10: =IF('IP Triangle'!D10>0,'IP Triangle'!E10/'IP Triangle'!D10,"") | E10: =IF('IP Triangle'!E10>0,'IP Triangle'!F10/'IP Triangle'!E10,"") | F10: =IF('IP Triangle'!F10>0,'IP Triangle'!G10/'IP Triangle'!F10,"") | G10: =IF('IP Triangle'!G10>0,'IP Triangle'!H10/'IP Triangle'!G10,"") | H10: =IF('IP Triangle'!H10>0,'IP Triangle'!I10/'IP Triangle'!H10,"") | I10: =IF('IP Triangle'!I10>0,'IP Triangle'!J10/'IP Triangle'!I10,"") | ... AK10: =IF('IP Triangle'!AK10>0,'IP Triangle'!AL10/'IP Triangle'!AK10,"")
A11: 2023-10 | B11: =IF('IP Triangle'!B11>0,'IP Triangle'!C11/'IP Triangle'!B11,"") | C11: =IF('IP Triangle'!C11>0,'IP Triangle'!D11/'IP Triangle'!C11,"") | D11: =IF('IP Triangle'!D11>0,'IP Triangle'!E11/'IP Triangle'!D11,"") | E11: =IF('IP Triangle'!E11>0,'IP Triangle'!F11/'IP Triangle'!E11,"") | F11: =IF('IP Triangle'!F11>0,'IP Triangle'!G11/'IP Triangle'!F11,"") | G11: =IF('IP Triangle'!G11>0,'IP Triangle'!H11/'IP Triangle'!G11,"") | H11: =IF('IP Triangle'!H11>0,'IP Triangle'!I11/'IP Triangle'!H11,"") | I11: =IF('IP Triangle'!I11>0,'IP Triangle'!J11/'IP Triangle'!I11,"") | ... AJ11: =IF('IP Triangle'!AJ11>0,'IP Triangle'!AK11/'IP Triangle'!AJ11,"")
A12: 2023-11 | B12: =IF('IP Triangle'!B12>0,'IP Triangle'!C12/'IP Triangle'!B12,"") | C12: =IF('IP Triangle'!C12>0,'IP Triangle'!D12/'IP Triangle'!C12,"") | D12: =IF('IP Triangle'!D12>0,'IP Triangle'!E12/'IP Triangle'!D12,"") | E12: =IF('IP Triangle'!E12>0,'IP Triangle'!F12/'IP Triangle'!E12,"") | F12: =IF('IP Triangle'!F12>0,'IP Triangle'!G12/'IP Triangle'!F12,"") | G12: =IF('IP Triangle'!G12>0,'IP Triangle'!H12/'IP Triangle'!G12,"") | H12: =IF('IP Triangle'!H12>0,'IP Triangle'!I12/'IP Triangle'!H12,"") | I12: =IF('IP Triangle'!I12>0,'IP Triangle'!J12/'IP Triangle'!I12,"") | ... AI12: =IF('IP Triangle'!AI12>0,'IP Triangle'!AJ12/'IP Triangle'!AI12,"")
A13: 2023-12 | B13: =IF('IP Triangle'!B13>0,'IP Triangle'!C13/'IP Triangle'!B13,"") | C13: =IF('IP Triangle'!C13>0,'IP Triangle'!D13/'IP Triangle'!C13,"") | D13: =IF('IP Triangle'!D13>0,'IP Triangle'!E13/'IP Triangle'!D13,"") | E13: =IF('IP Triangle'!E13>0,'IP Triangle'!F13/'IP Triangle'!E13,"") | F13: =IF('IP Triangle'!F13>0,'IP Triangle'!G13/'IP Triangle'!F13,"") | G13: =IF('IP Triangle'!G13>0,'IP Triangle'!H13/'IP Triangle'!G13,"") | H13: =IF('IP Triangle'!H13>0,'IP Triangle'!I13/'IP Triangle'!H13,"") | I13: =IF('IP Triangle'!I13>0,'IP Triangle'!J13/'IP Triangle'!I13,"") | ... AH13: =IF('IP Triangle'!AH13>0,'IP Triangle'!AI13/'IP Triangle'!AH13,"")
A14: 2024-01 | B14: =IF('IP Triangle'!B14>0,'IP Triangle'!C14/'IP Triangle'!B14,"") | C14: =IF('IP Triangle'!C14>0,'IP Triangle'!D14/'IP Triangle'!C14,"") | D14: =IF('IP Triangle'!D14>0,'IP Triangle'!E14/'IP Triangle'!D14,"") | E14: =IF('IP Triangle'!E14>0,'IP Triangle'!F14/'IP Triangle'!E14,"") | F14: =IF('IP Triangle'!F14>0,'IP Triangle'!G14/'IP Triangle'!F14,"") | G14: =IF('IP Triangle'!G14>0,'IP Triangle'!H14/'IP Triangle'!G14,"") | H14: =IF('IP Triangle'!H14>0,'IP Triangle'!I14/'IP Triangle'!H14,"") | I14: =IF('IP Triangle'!I14>0,'IP Triangle'!J14/'IP Triangle'!I14,"") | ... AG14: =IF('IP Triangle'!AG14>0,'IP Triangle'!AH14/'IP Triangle'!AG14,"")
A15: 2024-02 | B15: =IF('IP Triangle'!B15>0,'IP Triangle'!C15/'IP Triangle'!B15,"") | C15: =IF('IP Triangle'!C15>0,'IP Triangle'!D15/'IP Triangle'!C15,"") | D15: =IF('IP Triangle'!D15>0,'IP Triangle'!E15/'IP Triangle'!D15,"") | E15: =IF('IP Triangle'!E15>0,'IP Triangle'!F15/'IP Triangle'!E15,"") | F15: =IF('IP Triangle'!F15>0,'IP Triangle'!G15/'IP Triangle'!F15,"") | G15: =IF('IP Triangle'!G15>0,'IP Triangle'!H15/'IP Triangle'!G15,"") | H15: =IF('IP Triangle'!H15>0,'IP Triangle'!I15/'IP Triangle'!H15,"") | I15: =IF('IP Triangle'!I15>0,'IP Triangle'!J15/'IP Triangle'!I15,"") | ... AF15: =IF('IP Triangle'!AF15>0,'IP Triangle'!AG15/'IP Triangle'!AF15,"")
A16: 2024-03 | B16: =IF('IP Triangle'!B16>0,'IP Triangle'!C16/'IP Triangle'!B16,"") | C16: =IF('IP Triangle'!C16>0,'IP Triangle'!D16/'IP Triangle'!C16,"") | D16: =IF('IP Triangle'!D16>0,'IP Triangle'!E16/'IP Triangle'!D16,"") | E16: =IF('IP Triangle'!E16>0,'IP Triangle'!F16/'IP Triangle'!E16,"") | F16: =IF('IP Triangle'!F16>0,'IP Triangle'!G16/'IP Triangle'!F16,"") | G16: =IF('IP Triangle'!G16>0,'IP Triangle'!H16/'IP Triangle'!G16,"") | H16: =IF('IP Triangle'!H16>0,'IP Triangle'!I16/'IP Triangle'!H16,"") | I16: =IF('IP Triangle'!I16>0,'IP Triangle'!J16/'IP Triangle'!I16,"") | ... AE16: =IF('IP Triangle'!AE16>0,'IP Triangle'!AF16/'IP Triangle'!AE16,"")
A17: 2024-04 | B17: =IF('IP Triangle'!B17>0,'IP Triangle'!C17/'IP Triangle'!B17,"") | C17: =IF('IP Triangle'!C17>0,'IP Triangle'!D17/'IP Triangle'!C17,"") | D17: =IF('IP Triangle'!D17>0,'IP Triangle'!E17/'IP Triangle'!D17,"") | E17: =IF('IP Triangle'!E17>0,'IP Triangle'!F17/'IP Triangle'!E17,"") | F17: =IF('IP Triangle'!F17>0,'IP Triangle'!G17/'IP Triangle'!F17,"") | G17: =IF('IP Triangle'!G17>0,'IP Triangle'!H17/'IP Triangle'!G17,"") | H17: =IF('IP Triangle'!H17>0,'IP Triangle'!I17/'IP Triangle'!H17,"") | I17: =IF('IP Triangle'!I17>0,'IP Triangle'!J17/'IP Triangle'!I17,"") | ... AD17: =IF('IP Triangle'!AD17>0,'IP Triangle'!AE17/'IP Triangle'!AD17,"")
A18: 2024-05 | B18: =IF('IP Triangle'!B18>0,'IP Triangle'!C18/'IP Triangle'!B18,"") | C18: =IF('IP Triangle'!C18>0,'IP Triangle'!D18/'IP Triangle'!C18,"") | D18: =IF('IP Triangle'!D18>0,'IP Triangle'!E18/'IP Triangle'!D18,"") | E18: =IF('IP Triangle'!E18>0,'IP Triangle'!F18/'IP Triangle'!E18,"") | F18: =IF('IP Triangle'!F18>0,'IP Triangle'!G18/'IP Triangle'!F18,"") | G18: =IF('IP Triangle'!G18>0,'IP Triangle'!H18/'IP Triangle'!G18,"") | H18: =IF('IP Triangle'!H18>0,'IP Triangle'!I18/'IP Triangle'!H18,"") | I18: =IF('IP Triangle'!I18>0,'IP Triangle'!J18/'IP Triangle'!I18,"") | ... AC18: =IF('IP Triangle'!AC18>0,'IP Triangle'!AD18/'IP Triangle'!AC18,"")
A19: 2024-06 | B19: =IF('IP Triangle'!B19>0,'IP Triangle'!C19/'IP Triangle'!B19,"") | C19: =IF('IP Triangle'!C19>0,'IP Triangle'!D19/'IP Triangle'!C19,"") | D19: =IF('IP Triangle'!D19>0,'IP Triangle'!E19/'IP Triangle'!D19,"") | E19: =IF('IP Triangle'!E19>0,'IP Triangle'!F19/'IP Triangle'!E19,"") | F19: =IF('IP Triangle'!F19>0,'IP Triangle'!G19/'IP Triangle'!F19,"") | G19: =IF('IP Triangle'!G19>0,'IP Triangle'!H19/'IP Triangle'!G19,"") | H19: =IF('IP Triangle'!H19>0,'IP Triangle'!I19/'IP Triangle'!H19,"") | I19: =IF('IP Triangle'!I19>0,'IP Triangle'!J19/'IP Triangle'!I19,"") | ... AB19: =IF('IP Triangle'!AB19>0,'IP Triangle'!AC19/'IP Triangle'!AB19,"")
A20: 2024-07 | B20: =IF('IP Triangle'!B20>0,'IP Triangle'!C20/'IP Triangle'!B20,"") | C20: =IF('IP Triangle'!C20>0,'IP Triangle'!D20/'IP Triangle'!C20,"") | D20: =IF('IP Triangle'!D20>0,'IP Triangle'!E20/'IP Triangle'!D20,"") | E20: =IF('IP Triangle'!E20>0,'IP Triangle'!F20/'IP Triangle'!E20,"") | F20: =IF('IP Triangle'!F20>0,'IP Triangle'!G20/'IP Triangle'!F20,"") | G20: =IF('IP Triangle'!G20>0,'IP Triangle'!H20/'IP Triangle'!G20,"") | H20: =IF('IP Triangle'!H20>0,'IP Triangle'!I20/'IP Triangle'!H20,"") | I20: =IF('IP Triangle'!I20>0,'IP Triangle'!J20/'IP Triangle'!I20,"") | ... AA20: =IF('IP Triangle'!AA20>0,'IP Triangle'!AB20/'IP Triangle'!AA20,"")
A21: 2024-08 | B21: =IF('IP Triangle'!B21>0,'IP Triangle'!C21/'IP Triangle'!B21,"") | C21: =IF('IP Triangle'!C21>0,'IP Triangle'!D21/'IP Triangle'!C21,"") | D21: =IF('IP Triangle'!D21>0,'IP Triangle'!E21/'IP Triangle'!D21,"") | E21: =IF('IP Triangle'!E21>0,'IP Triangle'!F21/'IP Triangle'!E21,"") | F21: =IF('IP Triangle'!F21>0,'IP Triangle'!G21/'IP Triangle'!F21,"") | G21: =IF('IP Triangle'!G21>0,'IP Triangle'!H21/'IP Triangle'!G21,"") | H21: =IF('IP Triangle'!H21>0,'IP Triangle'!I21/'IP Triangle'!H21,"") | I21: =IF('IP Triangle'!I21>0,'IP Triangle'!J21/'IP Triangle'!I21,"") | ... Z21: =IF('IP Triangle'!Z21>0,'IP Triangle'!AA21/'IP Triangle'!Z21,"")
A22: 2024-09 | B22: =IF('IP Triangle'!B22>0,'IP Triangle'!C22/'IP Triangle'!B22,"") | C22: =IF('IP Triangle'!C22>0,'IP Triangle'!D22/'IP Triangle'!C22,"") | D22: =IF('IP Triangle'!D22>0,'IP Triangle'!E22/'IP Triangle'!D22,"") | E22: =IF('IP Triangle'!E22>0,'IP Triangle'!F22/'IP Triangle'!E22,"") | F22: =IF('IP Triangle'!F22>0,'IP Triangle'!G22/'IP Triangle'!F22,"") | G22: =IF('IP Triangle'!G22>0,'IP Triangle'!H22/'IP Triangle'!G22,"") | H22: =IF('IP Triangle'!H22>0,'IP Triangle'!I22/'IP Triangle'!H22,"") | I22: =IF('IP Triangle'!I22>0,'IP Triangle'!J22/'IP Triangle'!I22,"") | ... Y22: =IF('IP Triangle'!Y22>0,'IP Triangle'!Z22/'IP Triangle'!Y22,"")
A23: 2024-10 | B23: =IF('IP Triangle'!B23>0,'IP Triangle'!C23/'IP Triangle'!B23,"") | C23: =IF('IP Triangle'!C23>0,'IP Triangle'!D23/'IP Triangle'!C23,"") | D23: =IF('IP Triangle'!D23>0,'IP Triangle'!E23/'IP Triangle'!D23,"") | E23: =IF('IP Triangle'!E23>0,'IP Triangle'!F23/'IP Triangle'!E23,"") | F23: =IF('IP Triangle'!F23>0,'IP Triangle'!G23/'IP Triangle'!F23,"") | G23: =IF('IP Triangle'!G23>0,'IP Triangle'!H23/'IP Triangle'!G23,"") | H23: =IF('IP Triangle'!H23>0,'IP Triangle'!I23/'IP Triangle'!H23,"") | I23: =IF('IP Triangle'!I23>0,'IP Triangle'!J23/'IP Triangle'!I23,"") | ... X23: =IF('IP Triangle'!X23>0,'IP Triangle'!Y23/'IP Triangle'!X23,"")
A24: 2024-11 | B24: =IF('IP Triangle'!B24>0,'IP Triangle'!C24/'IP Triangle'!B24,"") | C24: =IF('IP Triangle'!C24>0,'IP Triangle'!D24/'IP Triangle'!C24,"") | D24: =IF('IP Triangle'!D24>0,'IP Triangle'!E24/'IP Triangle'!D24,"") | E24: =IF('IP Triangle'!E24>0,'IP Triangle'!F24/'IP Triangle'!E24,"") | F24: =IF('IP Triangle'!F24>0,'IP Triangle'!G24/'IP Triangle'!F24,"") | G24: =IF('IP Triangle'!G24>0,'IP Triangle'!H24/'IP Triangle'!G24,"") | H24: =IF('IP Triangle'!H24>0,'IP Triangle'!I24/'IP Triangle'!H24,"") | I24: =IF('IP Triangle'!I24>0,'IP Triangle'!J24/'IP Triangle'!I24,"") | ... W24: =IF('IP Triangle'!W24>0,'IP Triangle'!X24/'IP Triangle'!W24,"")
A25: 2024-12 | B25: =IF('IP Triangle'!B25>0,'IP Triangle'!C25/'IP Triangle'!B25,"") | C25: =IF('IP Triangle'!C25>0,'IP Triangle'!D25/'IP Triangle'!C25,"") | D25: =IF('IP Triangle'!D25>0,'IP Triangle'!E25/'IP Triangle'!D25,"") | E25: =IF('IP Triangle'!E25>0,'IP Triangle'!F25/'IP Triangle'!E25,"") | F25: =IF('IP Triangle'!F25>0,'IP Triangle'!G25/'IP Triangle'!F25,"") | G25: =IF('IP Triangle'!G25>0,'IP Triangle'!H25/'IP Triangle'!G25,"") | H25: =IF('IP Triangle'!H25>0,'IP Triangle'!I25/'IP Triangle'!H25,"") | I25: =IF('IP Triangle'!I25>0,'IP Triangle'!J25/'IP Triangle'!I25,"") | ... V25: =IF('IP Triangle'!V25>0,'IP Triangle'!W25/'IP Triangle'!V25,"")
A26: 2025-01 | B26: =IF('IP Triangle'!B26>0,'IP Triangle'!C26/'IP Triangle'!B26,"") | C26: =IF('IP Triangle'!C26>0,'IP Triangle'!D26/'IP Triangle'!C26,"") | D26: =IF('IP Triangle'!D26>0,'IP Triangle'!E26/'IP Triangle'!D26,"") | E26: =IF('IP Triangle'!E26>0,'IP Triangle'!F26/'IP Triangle'!E26,"") | F26: =IF('IP Triangle'!F26>0,'IP Triangle'!G26/'IP Triangle'!F26,"") | G26: =IF('IP Triangle'!G26>0,'IP Triangle'!H26/'IP Triangle'!G26,"") | H26: =IF('IP Triangle'!H26>0,'IP Triangle'!I26/'IP Triangle'!H26,"") | I26: =IF('IP Triangle'!I26>0,'IP Triangle'!J26/'IP Triangle'!I26,"") | ... U26: =IF('IP Triangle'!U26>0,'IP Triangle'!V26/'IP Triangle'!U26,"")
A27: 2025-02 | B27: =IF('IP Triangle'!B27>0,'IP Triangle'!C27/'IP Triangle'!B27,"") | C27: =IF('IP Triangle'!C27>0,'IP Triangle'!D27/'IP Triangle'!C27,"") | D27: =IF('IP Triangle'!D27>0,'IP Triangle'!E27/'IP Triangle'!D27,"") | E27: =IF('IP Triangle'!E27>0,'IP Triangle'!F27/'IP Triangle'!E27,"") | F27: =IF('IP Triangle'!F27>0,'IP Triangle'!G27/'IP Triangle'!F27,"") | G27: =IF('IP Triangle'!G27>0,'IP Triangle'!H27/'IP Triangle'!G27,"") | H27: =IF('IP Triangle'!H27>0,'IP Triangle'!I27/'IP Triangle'!H27,"") | I27: =IF('IP Triangle'!I27>0,'IP Triangle'!J27/'IP Triangle'!I27,"") | ... T27: =IF('IP Triangle'!T27>0,'IP Triangle'!U27/'IP Triangle'!T27,"")
A28: 2025-03 | B28: =IF('IP Triangle'!B28>0,'IP Triangle'!C28/'IP Triangle'!B28,"") | C28: =IF('IP Triangle'!C28>0,'IP Triangle'!D28/'IP Triangle'!C28,"") | D28: =IF('IP Triangle'!D28>0,'IP Triangle'!E28/'IP Triangle'!D28,"") | E28: =IF('IP Triangle'!E28>0,'IP Triangle'!F28/'IP Triangle'!E28,"") | F28: =IF('IP Triangle'!F28>0,'IP Triangle'!G28/'IP Triangle'!F28,"") | G28: =IF('IP Triangle'!G28>0,'IP Triangle'!H28/'IP Triangle'!G28,"") | H28: =IF('IP Triangle'!H28>0,'IP Triangle'!I28/'IP Triangle'!H28,"") | I28: =IF('IP Triangle'!I28>0,'IP Triangle'!J28/'IP Triangle'!I28,"") | ... S28: =IF('IP Triangle'!S28>0,'IP Triangle'!T28/'IP Triangle'!S28,"")
A29: 2025-04 | B29: =IF('IP Triangle'!B29>0,'IP Triangle'!C29/'IP Triangle'!B29,"") | C29: =IF('IP Triangle'!C29>0,'IP Triangle'!D29/'IP Triangle'!C29,"") | D29: =IF('IP Triangle'!D29>0,'IP Triangle'!E29/'IP Triangle'!D29,"") | E29: =IF('IP Triangle'!E29>0,'IP Triangle'!F29/'IP Triangle'!E29,"") | F29: =IF('IP Triangle'!F29>0,'IP Triangle'!G29/'IP Triangle'!F29,"") | G29: =IF('IP Triangle'!G29>0,'IP Triangle'!H29/'IP Triangle'!G29,"") | H29: =IF('IP Triangle'!H29>0,'IP Triangle'!I29/'IP Triangle'!H29,"") | I29: =IF('IP Triangle'!I29>0,'IP Triangle'!J29/'IP Triangle'!I29,"") | ... R29: =IF('IP Triangle'!R29>0,'IP Triangle'!S29/'IP Triangle'!R29,"")
A30: 2025-05 | B30: =IF('IP Triangle'!B30>0,'IP Triangle'!C30/'IP Triangle'!B30,"") | C30: =IF('IP Triangle'!C30>0,'IP Triangle'!D30/'IP Triangle'!C30,"") | D30: =IF('IP Triangle'!D30>0,'IP Triangle'!E30/'IP Triangle'!D30,"") | E30: =IF('IP Triangle'!E30>0,'IP Triangle'!F30/'IP Triangle'!E30,"") | F30: =IF('IP Triangle'!F30>0,'IP Triangle'!G30/'IP Triangle'!F30,"") | G30: =IF('IP Triangle'!G30>0,'IP Triangle'!H30/'IP Triangle'!G30,"") | H30: =IF('IP Triangle'!H30>0,'IP Triangle'!I30/'IP Triangle'!H30,"") | I30: =IF('IP Triangle'!I30>0,'IP Triangle'!J30/'IP Triangle'!I30,"") | ... Q30: =IF('IP Triangle'!Q30>0,'IP Triangle'!R30/'IP Triangle'!Q30,"")
A31: 2025-06 | B31: =IF('IP Triangle'!B31>0,'IP Triangle'!C31/'IP Triangle'!B31,"") | C31: =IF('IP Triangle'!C31>0,'IP Triangle'!D31/'IP Triangle'!C31,"") | D31: =IF('IP Triangle'!D31>0,'IP Triangle'!E31/'IP Triangle'!D31,"") | E31: =IF('IP Triangle'!E31>0,'IP Triangle'!F31/'IP Triangle'!E31,"") | F31: =IF('IP Triangle'!F31>0,'IP Triangle'!G31/'IP Triangle'!F31,"") | G31: =IF('IP Triangle'!G31>0,'IP Triangle'!H31/'IP Triangle'!G31,"") | H31: =IF('IP Triangle'!H31>0,'IP Triangle'!I31/'IP Triangle'!H31,"") | I31: =IF('IP Triangle'!I31>0,'IP Triangle'!J31/'IP Triangle'!I31,"") | ... P31: =IF('IP Triangle'!P31>0,'IP Triangle'!Q31/'IP Triangle'!P31,"")
A32: 2025-07 | B32: =IF('IP Triangle'!B32>0,'IP Triangle'!C32/'IP Triangle'!B32,"") | C32: =IF('IP Triangle'!C32>0,'IP Triangle'!D32/'IP Triangle'!C32,"") | D32: =IF('IP Triangle'!D32>0,'IP Triangle'!E32/'IP Triangle'!D32,"") | E32: =IF('IP Triangle'!E32>0,'IP Triangle'!F32/'IP Triangle'!E32,"") | F32: =IF('IP Triangle'!F32>0,'IP Triangle'!G32/'IP Triangle'!F32,"") | G32: =IF('IP Triangle'!G32>0,'IP Triangle'!H32/'IP Triangle'!G32,"") | H32: =IF('IP Triangle'!H32>0,'IP Triangle'!I32/'IP Triangle'!H32,"") | I32: =IF('IP Triangle'!I32>0,'IP Triangle'!J32/'IP Triangle'!I32,"") | ... O32: =IF('IP Triangle'!O32>0,'IP Triangle'!P32/'IP Triangle'!O32,"")
A33: 2025-08 | B33: =IF('IP Triangle'!B33>0,'IP Triangle'!C33/'IP Triangle'!B33,"") | C33: =IF('IP Triangle'!C33>0,'IP Triangle'!D33/'IP Triangle'!C33,"") | D33: =IF('IP Triangle'!D33>0,'IP Triangle'!E33/'IP Triangle'!D33,"") | E33: =IF('IP Triangle'!E33>0,'IP Triangle'!F33/'IP Triangle'!E33,"") | F33: =IF('IP Triangle'!F33>0,'IP Triangle'!G33/'IP Triangle'!F33,"") | G33: =IF('IP Triangle'!G33>0,'IP Triangle'!H33/'IP Triangle'!G33,"") | H33: =IF('IP Triangle'!H33>0,'IP Triangle'!I33/'IP Triangle'!H33,"") | I33: =IF('IP Triangle'!I33>0,'IP Triangle'!J33/'IP Triangle'!I33,"") | ... N33: =IF('IP Triangle'!N33>0,'IP Triangle'!O33/'IP Triangle'!N33,"")
A34: 2025-09 | B34: =IF('IP Triangle'!B34>0,'IP Triangle'!C34/'IP Triangle'!B34,"") | C34: =IF('IP Triangle'!C34>0,'IP Triangle'!D34/'IP Triangle'!C34,"") | D34: =IF('IP Triangle'!D34>0,'IP Triangle'!E34/'IP Triangle'!D34,"") | E34: =IF('IP Triangle'!E34>0,'IP Triangle'!F34/'IP Triangle'!E34,"") | F34: =IF('IP Triangle'!F34>0,'IP Triangle'!G34/'IP Triangle'!F34,"") | G34: =IF('IP Triangle'!G34>0,'IP Triangle'!H34/'IP Triangle'!G34,"") | H34: =IF('IP Triangle'!H34>0,'IP Triangle'!I34/'IP Triangle'!H34,"") | I34: =IF('IP Triangle'!I34>0,'IP Triangle'!J34/'IP Triangle'!I34,"") | ... M34: =IF('IP Triangle'!M34>0,'IP Triangle'!N34/'IP Triangle'!M34,"")
A35: 2025-10 | B35: =IF('IP Triangle'!B35>0,'IP Triangle'!C35/'IP Triangle'!B35,"") | C35: =IF('IP Triangle'!C35>0,'IP Triangle'!D35/'IP Triangle'!C35,"") | D35: =IF('IP Triangle'!D35>0,'IP Triangle'!E35/'IP Triangle'!D35,"") | E35: =IF('IP Triangle'!E35>0,'IP Triangle'!F35/'IP Triangle'!E35,"") | F35: =IF('IP Triangle'!F35>0,'IP Triangle'!G35/'IP Triangle'!F35,"") | G35: =IF('IP Triangle'!G35>0,'IP Triangle'!H35/'IP Triangle'!G35,"") | H35: =IF('IP Triangle'!H35>0,'IP Triangle'!I35/'IP Triangle'!H35,"") | I35: =IF('IP Triangle'!I35>0,'IP Triangle'!J35/'IP Triangle'!I35,"") | ... L35: =IF('IP Triangle'!L35>0,'IP Triangle'!M35/'IP Triangle'!L35,"")
A36: 2025-11 | B36: =IF('IP Triangle'!B36>0,'IP Triangle'!C36/'IP Triangle'!B36,"") | C36: =IF('IP Triangle'!C36>0,'IP Triangle'!D36/'IP Triangle'!C36,"") | D36: =IF('IP Triangle'!D36>0,'IP Triangle'!E36/'IP Triangle'!D36,"") | E36: =IF('IP Triangle'!E36>0,'IP Triangle'!F36/'IP Triangle'!E36,"") | F36: =IF('IP Triangle'!F36>0,'IP Triangle'!G36/'IP Triangle'!F36,"") | G36: =IF('IP Triangle'!G36>0,'IP Triangle'!H36/'IP Triangle'!G36,"") | H36: =IF('IP Triangle'!H36>0,'IP Triangle'!I36/'IP Triangle'!H36,"") | I36: =IF('IP Triangle'!I36>0,'IP Triangle'!J36/'IP Triangle'!I36,"") | ... K36: =IF('IP Triangle'!K36>0,'IP Triangle'!L36/'IP Triangle'!K36,"")
A37: 2025-12 | B37: =IF('IP Triangle'!B37>0,'IP Triangle'!C37/'IP Triangle'!B37,"") | C37: =IF('IP Triangle'!C37>0,'IP Triangle'!D37/'IP Triangle'!C37,"") | D37: =IF('IP Triangle'!D37>0,'IP Triangle'!E37/'IP Triangle'!D37,"") | E37: =IF('IP Triangle'!E37>0,'IP Triangle'!F37/'IP Triangle'!E37,"") | F37: =IF('IP Triangle'!F37>0,'IP Triangle'!G37/'IP Triangle'!F37,"") | G37: =IF('IP Triangle'!G37>0,'IP Triangle'!H37/'IP Triangle'!G37,"") | H37: =IF('IP Triangle'!H37>0,'IP Triangle'!I37/'IP Triangle'!H37,"") | I37: =IF('IP Triangle'!I37>0,'IP Triangle'!J37/'IP Triangle'!I37,"") | J37: =IF('IP Triangle'!J37>0,'IP Triangle'!K37/'IP Triangle'!J37,"")
A38: 2026-01 | B38: =IF('IP Triangle'!B38>0,'IP Triangle'!C38/'IP Triangle'!B38,"") | C38: =IF('IP Triangle'!C38>0,'IP Triangle'!D38/'IP Triangle'!C38,"") | D38: =IF('IP Triangle'!D38>0,'IP Triangle'!E38/'IP Triangle'!D38,"") | E38: =IF('IP Triangle'!E38>0,'IP Triangle'!F38/'IP Triangle'!E38,"") | F38: =IF('IP Triangle'!F38>0,'IP Triangle'!G38/'IP Triangle'!F38,"") | G38: =IF('IP Triangle'!G38>0,'IP Triangle'!H38/'IP Triangle'!G38,"") | H38: =IF('IP Triangle'!H38>0,'IP Triangle'!I38/'IP Triangle'!H38,"") | I38: =IF('IP Triangle'!I38>0,'IP Triangle'!J38/'IP Triangle'!I38,"")
A39: 2026-02 | B39: =IF('IP Triangle'!B39>0,'IP Triangle'!C39/'IP Triangle'!B39,"") | C39: =IF('IP Triangle'!C39>0,'IP Triangle'!D39/'IP Triangle'!C39,"") | D39: =IF('IP Triangle'!D39>0,'IP Triangle'!E39/'IP Triangle'!D39,"") | E39: =IF('IP Triangle'!E39>0,'IP Triangle'!F39/'IP Triangle'!E39,"") | F39: =IF('IP Triangle'!F39>0,'IP Triangle'!G39/'IP Triangle'!F39,"") | G39: =IF('IP Triangle'!G39>0,'IP Triangle'!H39/'IP Triangle'!G39,"") | H39: =IF('IP Triangle'!H39>0,'IP Triangle'!I39/'IP Triangle'!H39,"")
A40: 2026-03 | B40: =IF('IP Triangle'!B40>0,'IP Triangle'!C40/'IP Triangle'!B40,"") | C40: =IF('IP Triangle'!C40>0,'IP Triangle'!D40/'IP Triangle'!C40,"") | D40: =IF('IP Triangle'!D40>0,'IP Triangle'!E40/'IP Triangle'!D40,"") | E40: =IF('IP Triangle'!E40>0,'IP Triangle'!F40/'IP Triangle'!E40,"") | F40: =IF('IP Triangle'!F40>0,'IP Triangle'!G40/'IP Triangle'!F40,"") | G40: =IF('IP Triangle'!G40>0,'IP Triangle'!H40/'IP Triangle'!G40,"")
...

Sheet IP Factors
A1: Lag | B1: 6-mo avg ex hi/lo | C1: Override | D1: Selected link ratio | E1: Completion factor | F1: Months used
A2: 0 | B2: =(SUM('IP Ratios'!B38,'IP Ratios'!B39,'IP Ratios'!B40,'IP Ratios'!B41,'IP Ratios'!B44,'IP Ratios'!B45)-MAX('IP Ratios'!B38,'IP Ratios'!B39,'IP Ratios'!B40,'IP Ratios'!B41,'IP Ratios'!B44,'IP Ratios'!B45)-MIN('IP Ratios'!B38,'IP Ratios'!B39,'IP Ratios'!B40,'IP Ratios'!B41,'IP Ratios'!B44,'IP Ratios'!B45))/(COUNT('IP Ratios'!B38,'IP Ratios'!B39,'IP Ratios'!B40,'IP Ratios'!B41,'IP Ratios'!B44,'IP Ratios'!B45)-2) | D2: =IF(ISNUMBER(C2),C2,B2) | E2: =1/PRODUCT(D2:D46) | F2: 2026-01, 2026-02, 2026-03, 2026-04, 2026-07, 2026-08
A3: 1 | B3: =(SUM('IP Ratios'!C37,'IP Ratios'!C38,'IP Ratios'!C39,'IP Ratios'!C40,'IP Ratios'!C43,'IP Ratios'!C44)-MAX('IP Ratios'!C37,'IP Ratios'!C38,'IP Ratios'!C39,'IP Ratios'!C40,'IP Ratios'!C43,'IP Ratios'!C44)-MIN('IP Ratios'!C37,'IP Ratios'!C38,'IP Ratios'!C39,'IP Ratios'!C40,'IP Ratios'!C43,'IP Ratios'!C44))/(COUNT('IP Ratios'!C37,'IP Ratios'!C38,'IP Ratios'!C39,'IP Ratios'!C40,'IP Ratios'!C43,'IP Ratios'!C44)-2) | D3: =IF(ISNUMBER(C3),C3,B3) | E3: =1/PRODUCT(D3:D46) | F3: 2025-12, 2026-01, 2026-02, 2026-03, 2026-06, 2026-07
A4: 2 | B4: =(SUM('IP Ratios'!D36,'IP Ratios'!D37,'IP Ratios'!D38,'IP Ratios'!D39,'IP Ratios'!D42,'IP Ratios'!D43)-MAX('IP Ratios'!D36,'IP Ratios'!D37,'IP Ratios'!D38,'IP Ratios'!D39,'IP Ratios'!D42,'IP Ratios'!D43)-MIN('IP Ratios'!D36,'IP Ratios'!D37,'IP Ratios'!D38,'IP Ratios'!D39,'IP Ratios'!D42,'IP Ratios'!D43))/(COUNT('IP Ratios'!D36,'IP Ratios'!D37,'IP Ratios'!D38,'IP Ratios'!D39,'IP Ratios'!D42,'IP Ratios'!D43)-2) | D4: =IF(ISNUMBER(C4),C4,B4) | E4: =1/PRODUCT(D4:D46) | F4: 2025-11, 2025-12, 2026-01, 2026-02, 2026-05, 2026-06
A5: 3 | B5: =(SUM('IP Ratios'!E35,'IP Ratios'!E36,'IP Ratios'!E37,'IP Ratios'!E38,'IP Ratios'!E41,'IP Ratios'!E42)-MAX('IP Ratios'!E35,'IP Ratios'!E36,'IP Ratios'!E37,'IP Ratios'!E38,'IP Ratios'!E41,'IP Ratios'!E42)-MIN('IP Ratios'!E35,'IP Ratios'!E36,'IP Ratios'!E37,'IP Ratios'!E38,'IP Ratios'!E41,'IP Ratios'!E42))/(COUNT('IP Ratios'!E35,'IP Ratios'!E36,'IP Ratios'!E37,'IP Ratios'!E38,'IP Ratios'!E41,'IP Ratios'!E42)-2) | D5: =IF(ISNUMBER(C5),C5,B5) | E5: =1/PRODUCT(D5:D46) | F5: 2025-10, 2025-11, 2025-12, 2026-01, 2026-04, 2026-05
A6: 4 | B6: =(SUM('IP Ratios'!F34,'IP Ratios'!F35,'IP Ratios'!F36,'IP Ratios'!F37,'IP Ratios'!F40,'IP Ratios'!F41)-MAX('IP Ratios'!F34,'IP Ratios'!F35,'IP Ratios'!F36,'IP Ratios'!F37,'IP Ratios'!F40,'IP Ratios'!F41)-MIN('IP Ratios'!F34,'IP Ratios'!F35,'IP Ratios'!F36,'IP Ratios'!F37,'IP Ratios'!F40,'IP Ratios'!F41))/(COUNT('IP Ratios'!F34,'IP Ratios'!F35,'IP Ratios'!F36,'IP Ratios'!F37,'IP Ratios'!F40,'IP Ratios'!F41)-2) | D6: =IF(ISNUMBER(C6),C6,B6) | E6: =1/PRODUCT(D6:D46) | F6: 2025-09, 2025-10, 2025-11, 2025-12, 2026-03, 2026-04
A7: 5 | B7: =(SUM('IP Ratios'!G33,'IP Ratios'!G34,'IP Ratios'!G35,'IP Ratios'!G36,'IP Ratios'!G39,'IP Ratios'!G40)-MAX('IP Ratios'!G33,'IP Ratios'!G34,'IP Ratios'!G35,'IP Ratios'!G36,'IP Ratios'!G39,'IP Ratios'!G40)-MIN('IP Ratios'!G33,'IP Ratios'!G34,'IP Ratios'!G35,'IP Ratios'!G36,'IP Ratios'!G39,'IP Ratios'!G40))/(COUNT('IP Ratios'!G33,'IP Ratios'!G34,'IP Ratios'!G35,'IP Ratios'!G36,'IP Ratios'!G39,'IP Ratios'!G40)-2) | D7: =IF(ISNUMBER(C7),C7,B7) | E7: =1/PRODUCT(D7:D46) | F7: 2025-08, 2025-09, 2025-10, 2025-11, 2026-02, 2026-03
A8: 6 | B8: =(SUM('IP Ratios'!H32,'IP Ratios'!H33,'IP Ratios'!H34,'IP Ratios'!H35,'IP Ratios'!H38,'IP Ratios'!H39)-MAX('IP Ratios'!H32,'IP Ratios'!H33,'IP Ratios'!H34,'IP Ratios'!H35,'IP Ratios'!H38,'IP Ratios'!H39)-MIN('IP Ratios'!H32,'IP Ratios'!H33,'IP Ratios'!H34,'IP Ratios'!H35,'IP Ratios'!H38,'IP Ratios'!H39))/(COUNT('IP Ratios'!H32,'IP Ratios'!H33,'IP Ratios'!H34,'IP Ratios'!H35,'IP Ratios'!H38,'IP Ratios'!H39)-2) | D8: =IF(ISNUMBER(C8),C8,B8) | E8: =1/PRODUCT(D8:D46) | F8: 2025-07, 2025-08, 2025-09, 2025-10, 2026-01, 2026-02
A9: 7 | B9: =(SUM('IP Ratios'!I31,'IP Ratios'!I32,'IP Ratios'!I33,'IP Ratios'!I34,'IP Ratios'!I37,'IP Ratios'!I38)-MAX('IP Ratios'!I31,'IP Ratios'!I32,'IP Ratios'!I33,'IP Ratios'!I34,'IP Ratios'!I37,'IP Ratios'!I38)-MIN('IP Ratios'!I31,'IP Ratios'!I32,'IP Ratios'!I33,'IP Ratios'!I34,'IP Ratios'!I37,'IP Ratios'!I38))/(COUNT('IP Ratios'!I31,'IP Ratios'!I32,'IP Ratios'!I33,'IP Ratios'!I34,'IP Ratios'!I37,'IP Ratios'!I38)-2) | D9: =IF(ISNUMBER(C9),C9,B9) | E9: =1/PRODUCT(D9:D46) | F9: 2025-06, 2025-07, 2025-08, 2025-09, 2025-12, 2026-01
A10: 8 | B10: =(SUM('IP Ratios'!J30,'IP Ratios'!J31,'IP Ratios'!J32,'IP Ratios'!J33,'IP Ratios'!J36,'IP Ratios'!J37)-MAX('IP Ratios'!J30,'IP Ratios'!J31,'IP Ratios'!J32,'IP Ratios'!J33,'IP Ratios'!J36,'IP Ratios'!J37)-MIN('IP Ratios'!J30,'IP Ratios'!J31,'IP Ratios'!J32,'IP Ratios'!J33,'IP Ratios'!J36,'IP Ratios'!J37))/(COUNT('IP Ratios'!J30,'IP Ratios'!J31,'IP Ratios'!J32,'IP Ratios'!J33,'IP Ratios'!J36,'IP Ratios'!J37)-2) | D10: =IF(ISNUMBER(C10),C10,B10) | E10: =1/PRODUCT(D10:D46) | F10: 2025-05, 2025-06, 2025-07, 2025-08, 2025-11, 2025-12
A11: 9 | B11: =(SUM('IP Ratios'!K29,'IP Ratios'!K30,'IP Ratios'!K31,'IP Ratios'!K32,'IP Ratios'!K35,'IP Ratios'!K36)-MAX('IP Ratios'!K29,'IP Ratios'!K30,'IP Ratios'!K31,'IP Ratios'!K32,'IP Ratios'!K35,'IP Ratios'!K36)-MIN('IP Ratios'!K29,'IP Ratios'!K30,'IP Ratios'!K31,'IP Ratios'!K32,'IP Ratios'!K35,'IP Ratios'!K36))/(COUNT('IP Ratios'!K29,'IP Ratios'!K30,'IP Ratios'!K31,'IP Ratios'!K32,'IP Ratios'!K35,'IP Ratios'!K36)-2) | D11: =IF(ISNUMBER(C11),C11,B11) | E11: =1/PRODUCT(D11:D46) | F11: 2025-04, 2025-05, 2025-06, 2025-07, 2025-10, 2025-11
A12: 10 | B12: =(SUM('IP Ratios'!L28,'IP Ratios'!L29,'IP Ratios'!L30,'IP Ratios'!L31,'IP Ratios'!L34,'IP Ratios'!L35)-MAX('IP Ratios'!L28,'IP Ratios'!L29,'IP Ratios'!L30,'IP Ratios'!L31,'IP Ratios'!L34,'IP Ratios'!L35)-MIN('IP Ratios'!L28,'IP Ratios'!L29,'IP Ratios'!L30,'IP Ratios'!L31,'IP Ratios'!L34,'IP Ratios'!L35))/(COUNT('IP Ratios'!L28,'IP Ratios'!L29,'IP Ratios'!L30,'IP Ratios'!L31,'IP Ratios'!L34,'IP Ratios'!L35)-2) | D12: =IF(ISNUMBER(C12),C12,B12) | E12: =1/PRODUCT(D12:D46) | F12: 2025-03, 2025-04, 2025-05, 2025-06, 2025-09, 2025-10
A13: 11 | B13: =(SUM('IP Ratios'!M27,'IP Ratios'!M28,'IP Ratios'!M29,'IP Ratios'!M30,'IP Ratios'!M33,'IP Ratios'!M34)-MAX('IP Ratios'!M27,'IP Ratios'!M28,'IP Ratios'!M29,'IP Ratios'!M30,'IP Ratios'!M33,'IP Ratios'!M34)-MIN('IP Ratios'!M27,'IP Ratios'!M28,'IP Ratios'!M29,'IP Ratios'!M30,'IP Ratios'!M33,'IP Ratios'!M34))/(COUNT('IP Ratios'!M27,'IP Ratios'!M28,'IP Ratios'!M29,'IP Ratios'!M30,'IP Ratios'!M33,'IP Ratios'!M34)-2) | D13: =IF(ISNUMBER(C13),C13,B13) | E13: =1/PRODUCT(D13:D46) | F13: 2025-02, 2025-03, 2025-04, 2025-05, 2025-08, 2025-09
A14: 12 | B14: =(SUM('IP Ratios'!N26,'IP Ratios'!N27,'IP Ratios'!N28,'IP Ratios'!N29,'IP Ratios'!N32,'IP Ratios'!N33)-MAX('IP Ratios'!N26,'IP Ratios'!N27,'IP Ratios'!N28,'IP Ratios'!N29,'IP Ratios'!N32,'IP Ratios'!N33)-MIN('IP Ratios'!N26,'IP Ratios'!N27,'IP Ratios'!N28,'IP Ratios'!N29,'IP Ratios'!N32,'IP Ratios'!N33))/(COUNT('IP Ratios'!N26,'IP Ratios'!N27,'IP Ratios'!N28,'IP Ratios'!N29,'IP Ratios'!N32,'IP Ratios'!N33)-2) | D14: =IF(ISNUMBER(C14),C14,B14) | E14: =1/PRODUCT(D14:D46) | F14: 2025-01, 2025-02, 2025-03, 2025-04, 2025-07, 2025-08
A15: 13 | B15: =(SUM('IP Ratios'!O25,'IP Ratios'!O26,'IP Ratios'!O27,'IP Ratios'!O28,'IP Ratios'!O31,'IP Ratios'!O32)-MAX('IP Ratios'!O25,'IP Ratios'!O26,'IP Ratios'!O27,'IP Ratios'!O28,'IP Ratios'!O31,'IP Ratios'!O32)-MIN('IP Ratios'!O25,'IP Ratios'!O26,'IP Ratios'!O27,'IP Ratios'!O28,'IP Ratios'!O31,'IP Ratios'!O32))/(COUNT('IP Ratios'!O25,'IP Ratios'!O26,'IP Ratios'!O27,'IP Ratios'!O28,'IP Ratios'!O31,'IP Ratios'!O32)-2) | D15: =IF(ISNUMBER(C15),C15,B15) | E15: =1/PRODUCT(D15:D46) | F15: 2024-12, 2025-01, 2025-02, 2025-03, 2025-06, 2025-07
A16: 14 | B16: =(SUM('IP Ratios'!P24,'IP Ratios'!P25,'IP Ratios'!P26,'IP Ratios'!P27,'IP Ratios'!P30,'IP Ratios'!P31)-MAX('IP Ratios'!P24,'IP Ratios'!P25,'IP Ratios'!P26,'IP Ratios'!P27,'IP Ratios'!P30,'IP Ratios'!P31)-MIN('IP Ratios'!P24,'IP Ratios'!P25,'IP Ratios'!P26,'IP Ratios'!P27,'IP Ratios'!P30,'IP Ratios'!P31))/(COUNT('IP Ratios'!P24,'IP Ratios'!P25,'IP Ratios'!P26,'IP Ratios'!P27,'IP Ratios'!P30,'IP Ratios'!P31)-2) | D16: =IF(ISNUMBER(C16),C16,B16) | E16: =1/PRODUCT(D16:D46) | F16: 2024-11, 2024-12, 2025-01, 2025-02, 2025-05, 2025-06
A17: 15 | B17: =(SUM('IP Ratios'!Q23,'IP Ratios'!Q24,'IP Ratios'!Q25,'IP Ratios'!Q26,'IP Ratios'!Q29,'IP Ratios'!Q30)-MAX('IP Ratios'!Q23,'IP Ratios'!Q24,'IP Ratios'!Q25,'IP Ratios'!Q26,'IP Ratios'!Q29,'IP Ratios'!Q30)-MIN('IP Ratios'!Q23,'IP Ratios'!Q24,'IP Ratios'!Q25,'IP Ratios'!Q26,'IP Ratios'!Q29,'IP Ratios'!Q30))/(COUNT('IP Ratios'!Q23,'IP Ratios'!Q24,'IP Ratios'!Q25,'IP Ratios'!Q26,'IP Ratios'!Q29,'IP Ratios'!Q30)-2) | D17: =IF(ISNUMBER(C17),C17,B17) | E17: =1/PRODUCT(D17:D46) | F17: 2024-10, 2024-11, 2024-12, 2025-01, 2025-04, 2025-05
A18: 16 | B18: =(SUM('IP Ratios'!R22,'IP Ratios'!R23,'IP Ratios'!R24,'IP Ratios'!R25,'IP Ratios'!R28,'IP Ratios'!R29)-MAX('IP Ratios'!R22,'IP Ratios'!R23,'IP Ratios'!R24,'IP Ratios'!R25,'IP Ratios'!R28,'IP Ratios'!R29)-MIN('IP Ratios'!R22,'IP Ratios'!R23,'IP Ratios'!R24,'IP Ratios'!R25,'IP Ratios'!R28,'IP Ratios'!R29))/(COUNT('IP Ratios'!R22,'IP Ratios'!R23,'IP Ratios'!R24,'IP Ratios'!R25,'IP Ratios'!R28,'IP Ratios'!R29)-2) | D18: =IF(ISNUMBER(C18),C18,B18) | E18: =1/PRODUCT(D18:D46) | F18: 2024-09, 2024-10, 2024-11, 2024-12, 2025-03, 2025-04
A19: 17 | B19: =(SUM('IP Ratios'!S21,'IP Ratios'!S22,'IP Ratios'!S23,'IP Ratios'!S24,'IP Ratios'!S27,'IP Ratios'!S28)-MAX('IP Ratios'!S21,'IP Ratios'!S22,'IP Ratios'!S23,'IP Ratios'!S24,'IP Ratios'!S27,'IP Ratios'!S28)-MIN('IP Ratios'!S21,'IP Ratios'!S22,'IP Ratios'!S23,'IP Ratios'!S24,'IP Ratios'!S27,'IP Ratios'!S28))/(COUNT('IP Ratios'!S21,'IP Ratios'!S22,'IP Ratios'!S23,'IP Ratios'!S24,'IP Ratios'!S27,'IP Ratios'!S28)-2) | D19: =IF(ISNUMBER(C19),C19,B19) | E19: =1/PRODUCT(D19:D46) | F19: 2024-08, 2024-09, 2024-10, 2024-11, 2025-02, 2025-03
A20: 18 | B20: =(SUM('IP Ratios'!T20,'IP Ratios'!T21,'IP Ratios'!T22,'IP Ratios'!T23,'IP Ratios'!T26,'IP Ratios'!T27)-MAX('IP Ratios'!T20,'IP Ratios'!T21,'IP Ratios'!T22,'IP Ratios'!T23,'IP Ratios'!T26,'IP Ratios'!T27)-MIN('IP Ratios'!T20,'IP Ratios'!T21,'IP Ratios'!T22,'IP Ratios'!T23,'IP Ratios'!T26,'IP Ratios'!T27))/(COUNT('IP Ratios'!T20,'IP Ratios'!T21,'IP Ratios'!T22,'IP Ratios'!T23,'IP Ratios'!T26,'IP Ratios'!T27)-2) | D20: =IF(ISNUMBER(C20),C20,B20) | E20: =1/PRODUCT(D20:D46) | F20: 2024-07, 2024-08, 2024-09, 2024-10, 2025-01, 2025-02
A21: 19 | B21: =(SUM('IP Ratios'!U19,'IP Ratios'!U20,'IP Ratios'!U21,'IP Ratios'!U22,'IP Ratios'!U25,'IP Ratios'!U26)-MAX('IP Ratios'!U19,'IP Ratios'!U20,'IP Ratios'!U21,'IP Ratios'!U22,'IP Ratios'!U25,'IP Ratios'!U26)-MIN('IP Ratios'!U19,'IP Ratios'!U20,'IP Ratios'!U21,'IP Ratios'!U22,'IP Ratios'!U25,'IP Ratios'!U26))/(COUNT('IP Ratios'!U19,'IP Ratios'!U20,'IP Ratios'!U21,'IP Ratios'!U22,'IP Ratios'!U25,'IP Ratios'!U26)-2) | D21: =IF(ISNUMBER(C21),C21,B21) | E21: =1/PRODUCT(D21:D46) | F21: 2024-06, 2024-07, 2024-08, 2024-09, 2024-12, 2025-01
A22: 20 | B22: =(SUM('IP Ratios'!V18,'IP Ratios'!V19,'IP Ratios'!V20,'IP Ratios'!V21,'IP Ratios'!V24,'IP Ratios'!V25)-MAX('IP Ratios'!V18,'IP Ratios'!V19,'IP Ratios'!V20,'IP Ratios'!V21,'IP Ratios'!V24,'IP Ratios'!V25)-MIN('IP Ratios'!V18,'IP Ratios'!V19,'IP Ratios'!V20,'IP Ratios'!V21,'IP Ratios'!V24,'IP Ratios'!V25))/(COUNT('IP Ratios'!V18,'IP Ratios'!V19,'IP Ratios'!V20,'IP Ratios'!V21,'IP Ratios'!V24,'IP Ratios'!V25)-2) | D22: =IF(ISNUMBER(C22),C22,B22) | E22: =1/PRODUCT(D22:D46) | F22: 2024-05, 2024-06, 2024-07, 2024-08, 2024-11, 2024-12
A23: 21 | B23: =(SUM('IP Ratios'!W17,'IP Ratios'!W18,'IP Ratios'!W19,'IP Ratios'!W20,'IP Ratios'!W23,'IP Ratios'!W24)-MAX('IP Ratios'!W17,'IP Ratios'!W18,'IP Ratios'!W19,'IP Ratios'!W20,'IP Ratios'!W23,'IP Ratios'!W24)-MIN('IP Ratios'!W17,'IP Ratios'!W18,'IP Ratios'!W19,'IP Ratios'!W20,'IP Ratios'!W23,'IP Ratios'!W24))/(COUNT('IP Ratios'!W17,'IP Ratios'!W18,'IP Ratios'!W19,'IP Ratios'!W20,'IP Ratios'!W23,'IP Ratios'!W24)-2) | D23: =IF(ISNUMBER(C23),C23,B23) | E23: =1/PRODUCT(D23:D46) | F23: 2024-04, 2024-05, 2024-06, 2024-07, 2024-10, 2024-11
A24: 22 | B24: =(SUM('IP Ratios'!X16,'IP Ratios'!X17,'IP Ratios'!X18,'IP Ratios'!X19,'IP Ratios'!X22,'IP Ratios'!X23)-MAX('IP Ratios'!X16,'IP Ratios'!X17,'IP Ratios'!X18,'IP Ratios'!X19,'IP Ratios'!X22,'IP Ratios'!X23)-MIN('IP Ratios'!X16,'IP Ratios'!X17,'IP Ratios'!X18,'IP Ratios'!X19,'IP Ratios'!X22,'IP Ratios'!X23))/(COUNT('IP Ratios'!X16,'IP Ratios'!X17,'IP Ratios'!X18,'IP Ratios'!X19,'IP Ratios'!X22,'IP Ratios'!X23)-2) | D24: =IF(ISNUMBER(C24),C24,B24) | E24: =1/PRODUCT(D24:D46) | F24: 2024-03, 2024-04, 2024-05, 2024-06, 2024-09, 2024-10
A25: 23 | B25: =(SUM('IP Ratios'!Y15,'IP Ratios'!Y16,'IP Ratios'!Y17,'IP Ratios'!Y18,'IP Ratios'!Y21,'IP Ratios'!Y22)-MAX('IP Ratios'!Y15,'IP Ratios'!Y16,'IP Ratios'!Y17,'IP Ratios'!Y18,'IP Ratios'!Y21,'IP Ratios'!Y22)-MIN('IP Ratios'!Y15,'IP Ratios'!Y16,'IP Ratios'!Y17,'IP Ratios'!Y18,'IP Ratios'!Y21,'IP Ratios'!Y22))/(COUNT('IP Ratios'!Y15,'IP Ratios'!Y16,'IP Ratios'!Y17,'IP Ratios'!Y18,'IP Ratios'!Y21,'IP Ratios'!Y22)-2) | D25: =IF(ISNUMBER(C25),C25,B25) | E25: =1/PRODUCT(D25:D46) | F25: 2024-02, 2024-03, 2024-04, 2024-05, 2024-08, 2024-09
A26: 24 | B26: =(SUM('IP Ratios'!Z14,'IP Ratios'!Z15,'IP Ratios'!Z16,'IP Ratios'!Z17,'IP Ratios'!Z20,'IP Ratios'!Z21)-MAX('IP Ratios'!Z14,'IP Ratios'!Z15,'IP Ratios'!Z16,'IP Ratios'!Z17,'IP Ratios'!Z20,'IP Ratios'!Z21)-MIN('IP Ratios'!Z14,'IP Ratios'!Z15,'IP Ratios'!Z16,'IP Ratios'!Z17,'IP Ratios'!Z20,'IP Ratios'!Z21))/(COUNT('IP Ratios'!Z14,'IP Ratios'!Z15,'IP Ratios'!Z16,'IP Ratios'!Z17,'IP Ratios'!Z20,'IP Ratios'!Z21)-2) | D26: =IF(ISNUMBER(C26),C26,B26) | E26: =1/PRODUCT(D26:D46) | F26: 2024-01, 2024-02, 2024-03, 2024-04, 2024-07, 2024-08
A27: 25 | B27: =(SUM('IP Ratios'!AA13,'IP Ratios'!AA14,'IP Ratios'!AA15,'IP Ratios'!AA16,'IP Ratios'!AA19,'IP Ratios'!AA20)-MAX('IP Ratios'!AA13,'IP Ratios'!AA14,'IP Ratios'!AA15,'IP Ratios'!AA16,'IP Ratios'!AA19,'IP Ratios'!AA20)-MIN('IP Ratios'!AA13,'IP Ratios'!AA14,'IP Ratios'!AA15,'IP Ratios'!AA16,'IP Ratios'!AA19,'IP Ratios'!AA20))/(COUNT('IP Ratios'!AA13,'IP Ratios'!AA14,'IP Ratios'!AA15,'IP Ratios'!AA16,'IP Ratios'!AA19,'IP Ratios'!AA20)-2) | D27: =IF(ISNUMBER(C27),C27,B27) | E27: =1/PRODUCT(D27:D46) | F27: 2023-12, 2024-01, 2024-02, 2024-03, 2024-06, 2024-07
